Workbook

Sheet TOC0
A1: Real Statistics Using Excel - Examples Workbook Regression 1
A2: Charles Zaiontz, 29 October 2018
A4: Copyright © 2013 - 2018 Charles Zaiontz
A6: Concise Table of Contents
A8: Linear Regression
A9: Multiple Regression
A10: Tables

Sheet TOC
A1: Real Statistics Using Excel - Examples Workbook Regression 1
A2: Charles Zaiontz, 29 October 2018
A4: Copyright © 2013 - 2018 Charles Zaiontz
A6: Table of Contents
A8: Linear Regression
A10: Method of least squares
B11: Regression line (Example 1)
A13: Regression analysis
B14: Using regression line for prediction (Example 1)
B15: Significance vs effect size (re correlation coefficient)
A17: Hypothesis testing whether the regression line is a good fit for the data
B18: Testing fit of regression line (Example 1)
A20: Hypothesis testing of the significance of the slope of the regression line
B21: Testing slope of regression line (Example 1)
B22: LINEST function (Figure 2)
B23: Regression data analysis tool (Figures 3 and 4)
B24: Comparing the slopes of two independent samples (Example 1 of Detail)
A26: Confidence and prediction intervals for forecasted values
B27: Confidence/prediction Intervals (Example 1)
B28: Testing intercept of regression line (Example 2)
B29: Plot
A31: Exponential regression
B32: Exponential Regression - linear regression (Example 1)
B33: LOGEST and GROWTH functions (Figure 4)
B34: Nonlinear regression via Solver, before (Example 1)
B35: Nonlinear regression via Solver, after (Example 1)
B36: Nonlinear regression via Newton's method (Example 1)
B37: Data analysis tool (Example 1)
A39: Power regression
B40: Log-log Regression (Example 1)
A42: Linear regression models for comparing means
B43: Regression to Compare Means (Example 1)
B44: Full results from data analysis tool for Example 1
B45: Regression to Compare Means (Example 2)
B46: Full results from data analysis tool for Example 2
A48: Total least squares regression
B49: Total least squares regression (Example 1)
B50: Comparison with ordinary linear regression
A52: Deming regression
B53: Deming regression with known variances (Example 1)
...

Sheet Reg 1
A1: Regression
D2: cov(x,y) | E2: =COVAR(A4:A18,B4:B18) -> -90.946667 | G2: =COVAR(A4:A18,B4:B18) | N2: Prediction using y = a + b * x
A3: Cig (x) | B3: Life Exp (y) | D3: varp(x) | E3: =VARP(A4:A18) -> 144.77333 | G3: =VARP(A4:A18) | I3: Data | K3: Prediction
A4: 5 | B4: 80 | D4: slope b | E4: =E2/E3 -> -0.62820041 | G4: =E2/E3 | I4: Cig (x) | J4: Life Exp (y) | K4: Life Exp (ŷ) | L4: Error (e) | N4: x | O4: ŷ
A5: 23 | B5: 78 | D5: intercept a | E5: =AVERAGE(B4:B18)-E4*AVERAGE(A4:A18) -> 85.720421 | G5: =AVERAGE(B4:B18)-E4*AVERAGE(A4:A18) | I5: 5 | J5: 80 | K5: =I5*$E$4+$E$5 -> 82.579419 | L5: =J5-K5 -> -2.5794192 | N5: 4 | O5: =N5*$E$4+$E$5 -> 83.20762
A6: 25 | B6: 60 | I6: 23 | J6: 78 | K6: =I6*$E$4+$E$5 -> 71.271812 | L6: =J6-K6 -> 6.7281881 | N6: 24 | O6: =N6*$E$4+$E$5 -> 70.643611
A7: 48 | B7: 53 | I7: 25 | J7: 60 | K7: =I7*$E$4+$E$5 -> 70.015411 | L7: =J7-K7 -> -10.015411 | N7: 44 | O7: =N7*$E$4+$E$5 -> 58.079603
A8: 17 | B8: 85 | I8: 48 | J8: 53 | K8: =I8*$E$4+$E$5 -> 55.566802 | L8: =J8-K8 -> -2.5668017
A9: 8 | B9: 84 | I9: 17 | J9: 85 | K9: =I9*$E$4+$E$5 -> 75.041014 | L9: =J9-K9 -> 9.9589857 | N9: Prediction using FORECAST
A10: 4 | B10: 73 | I10: 8 | J10: 84 | K10: =I10*$E$4+$E$5 -> 80.694818 | L10: =J10-K10 -> 3.305182
A11: 26 | B11: 79 | I11: 4 | J11: 73 | K11: =I11*$E$4+$E$5 -> 83.20762 | L11: =J11-K11 -> -10.20762 | N11: x | O11: ŷ
A12: 11 | B12: 81 | I12: 26 | J12: 79 | K12: =I12*$E$4+$E$5 -> 69.387211 | L12: =J12-K12 -> 9.6127893 | N12: 4 | O12: =FORECAST(N12,$J$5:$J$19,$I$5:$I$19) -> 83.20762
A13: 19 | B13: 75 | I13: 11 | J13: 81 | K13: =I13*$E$4+$E$5 -> 78.810217 | L13: =J13-K13 -> 2.1897833 | N13: 24 | O13: =FORECAST(N13,$J$5:$J$19,$I$5:$I$19) -> 70.643611
A14: 14 | B14: 68 | I14: 19 | J14: 75 | K14: =I14*$E$4+$E$5 -> 73.784613 | L14: =J14-K14 -> 1.2153865 | N14: 44 | O14: =FORECAST(N14,$J$5:$J$19,$I$5:$I$19) -> 58.079603
A15: 35 | B15: 72 | I15: 14 | J15: 68 | K15: =I15*$E$4+$E$5 -> 76.925616 | L15: =J15-K15 -> -8.9256155
A16: 29 | B16: 58 | I16: 35 | J16: 72 | K16: =I16*$E$4+$E$5 -> 63.733407 | L16: =J16-K16 -> 8.266593 | N16: Prediction using TREND
A17: 4 | B17: 92 | I17: 29 | J17: 58 | K17: =I17*$E$4+$E$5 -> 67.502609 | L17: =J17-K17 -> -9.5026094
A18: 23 | B18: 65 | I18: 4 | J18: 92 | K18: =I18*$E$4+$E$5 -> 83.20762 | L18: =J18-K18 -> 8.7923804 | N18: x | O18: ŷ
I19: 23 | J19: 65 | K19: =I19*$E$4+$E$5 -> 71.271812 | L19: =J19-K19 -> -6.2718119 | N19: 4 | O19: {=TREND(J5:J19,I5:I19,N19:N21)} -> 83.20762
N20: 24 | O20: 70.643611
I21: =AVERAGE(I5:I19) -> 19.4 | J21: =AVERAGE(J5:J19) -> 73.533333 | N21: 44 | O21: 58.079603
I22: =STDEV(I5:I19) -> 12.454489 | J22: =STDEV(J5:J19) -> 10.966616

Sheet Reg 2
A1: Regression Testing | J1: Alternative 1 | T1: Alternative 2
A3: Cig (x) | B3: Life Exp (y) | D3: n | E3: =COUNT(A4:A18) -> 15 | J3: Data | L3: Prediction | P3: SS | Q3: df | R3: MS | T3: Data | V3: Prediction | W3: SS | AB3: SS | AC3: df | AD3: MS | AF3: Alternative ways to calculate SS-Res | AJ3: Correlations | AM3: Use of LINEST
A4: 5 | B4: 80 | D4: r | E4: =CORREL(A4:A18,B4:B18) -> -0.71343017 | J4: Cig (x) | K4: Life Exp (y) | L4: Life Exp (ŷ) | M4: Error (e) | O4: T | P4: =DEVSQ(K5:K19) -> 1683.7333 | Q4: =COUNT(K5:K19)-1 -> 14 | R4: =P4/Q4 -> 120.26667 | T4: Cig (x) | U4: Life Exp (y) | V4: Life Exp (ŷ) | W4: T | X4: Reg | Y4: Res | AA4: T | AB4: =W20 -> 1683.7333 | AC4: =U21-1 -> 14 | AD4: =AB4/AC4 -> 120.26667
A5: 23 | B5: 78 | J5: 5 | K5: 80 | L5: =FORECAST(J5,$K$5:$K$19,$J$5:$J$19) -> 82.579419 | M5: =K5-L5 -> -2.5794192 | O5: Reg | P5: =DEVSQ(L5:L19) -> 856.99099 | Q5: 1 | R5: =P5/Q5 -> 856.99099 | T5: 5 | U5: 80 | V5: =FORECAST(T5,$K$5:$K$19,$J$5:$J$19) -> 82.579419 | W5: =(U5-$U$22)^2 -> 41.817778 | X5: =(V5-$U$22)^2 -> 81.831669 | Y5: =(U5-V5)^2 -> 6.6534032 | AA5: Reg | AB5: =X20 -> 856.99099 | AC5: 1 | AD5: =AB5/AC5 -> 856.99099 | AF5: =AB4-AB5 -> 826.74234 | AH5: =AB4-AB5 | AJ5: x and y | AK5: =CORREL(T5:T19,U5:U19) -> -0.71343017 | AM5: Slope (b) | AN5: {=LINEST(B4:B18,A4:A18,TRUE,TRUE)} -> -0.62820041 | AO5: 85.720421 | AP5: Intercept (a)
A6: 25 | B6: 60 | E6: SS | F6: df | G6: MS | J6: 23 | K6: 78 | L6: =FORECAST(J6,$K$5:$K$19,$J$5:$J$19) -> 71.271812 | M6: =K6-L6 -> 6.7281881 | O6: Res | P6: =DEVSQ(M5:M19) -> 826.74234 | Q6: =Q4-1 -> 13 | R6: =P6/Q6 -> 63.595565 | T6: 23 | U6: 78 | V6: =FORECAST(T6,$K$5:$K$19,$J$5:$J$19) -> 71.271812 | W6: =(U6-$U$22)^2 -> 19.951111 | X6: =(V6-$U$22)^2 -> 5.1144793 | Y6: =(U6-V6)^2 -> 45.268515 | AA6: Res | AB6: =Y20 -> 826.74234 | AC6: =AC4-1 -> 13 | AD6: =AB6/AC6 -> 63.595565 | AF6: =SUMXMY2(U5:U19,V5:V19) -> 826.74234 | AH6: =SUMXMY2(U5:U19,V5:V19) | AJ6: x and ŷ | AK6: =CORREL(T5:T19,V5:V19) -> -1 | AM6: S.E. of slope (sb) | AN6: 0.17112895 | AO6: 3.9065908 | AP6: S.E. of intercept (sa)
A7: 48 | B7: 53 | D7: T | E7: =DEVSQ(B4:B18) -> 1683.7333 | F7: =E3-1 -> 14 | G7: =E7/F7 -> 120.26667 | J7: 25 | K7: 60 | L7: =FORECAST(J7,$K$5:$K$19,$J$5:$J$19) -> 70.015411 | M7: =K7-L7 -> -10.015411 | T7: 25 | U7: 60 | V7: =FORECAST(T7,$K$5:$K$19,$J$5:$J$19) -> 70.015411 | W7: =(U7-$U$22)^2 -> 183.15111 | X7: =(V7-$U$22)^2 -> 12.375777 | Y7: =(U7-V7)^2 -> 100.30846 | AJ7: y and ŷ | AK7: =CORREL(U5:U19,V5:V19) -> 0.71343017 | AM7: R Square | AN7: 0.50898261 | AO7: 7.9746827 | AP7: S.E. of estimate (sRes)
A8: 17 | B8: 85 | D8: Reg | E8: =E4^2*E7 -> 856.99099 | F8: 1 | G8: =E8/F8 -> 856.99099 | J8: 48 | K8: 53 | L8: =FORECAST(J8,$K$5:$K$19,$J$5:$J$19) -> 55.566802 | M8: =K8-L8 -> -2.5668017 | T8: 48 | U8: 53 | V8: =FORECAST(T8,$K$5:$K$19,$J$5:$J$19) -> 55.566802 | W8: =(U8-$U$22)^2 -> 421.61778 | X8: =(V8-$U$22)^2 -> 322.79626 | Y8: =(U8-V8)^2 -> 6.5884712 | AM8: F | AN8: 13.475641 | AO8: 13 | AP8: dfRes
A9: 8 | B9: 84 | D9: Res | E9: =E7-E8 -> 826.74234 | F9: =F7-1 -> 13 | G9: =E9/F9 -> 63.595565 | J9: 17 | K9: 85 | L9: =FORECAST(J9,$K$5:$K$19,$J$5:$J$19) -> 75.041014 | M9: =K9-L9 -> 9.9589857 | T9: 17 | U9: 85 | V9: =FORECAST(T9,$K$5:$K$19,$J$5:$J$19) -> 75.041014 | W9: =(U9-$U$22)^2 -> 131.48444 | X9: =(V9-$U$22)^2 -> 2.2731019 | Y9: =(U9-V9)^2 -> 99.181396 | AM9: SSReg | AN9: 856.99099 | AO9: 826.74234 | AP9: SSRes
A10: 4 | B10: 73 | J10: 8 | K10: 84 | L10: =FORECAST(J10,$K$5:$K$19,$J$5:$J$19) -> 80.694818 | M10: =K10-L10 -> 3.305182 | T10: 8 | U10: 84 | V10: =FORECAST(T10,$K$5:$K$19,$J$5:$J$19) -> 80.694818 | W10: =(U10-$U$22)^2 -> 109.55111 | X10: =(V10-$U$22)^2 -> 51.286862 | Y10: =(U10-V10)^2 -> 10.924228
A11: 26 | B11: 79 | D11: F | E11: =G8/G9 -> 13.475641 | G11: =G8/G9 | J11: 4 | K11: 73 | L11: =FORECAST(J11,$K$5:$K$19,$J$5:$J$19) -> 83.20762 | M11: =K11-L11 -> -10.20762 | T11: 4 | U11: 73 | V11: =FORECAST(T11,$K$5:$K$19,$J$5:$J$19) -> 83.20762 | W11: =(U11-$U$22)^2 -> 0.28444444 | X11: =(V11-$U$22)^2 -> 93.591814 | Y11: =(U11-V11)^2 -> 104.1955
A12: 11 | B12: 81 | D12: alpha | E12: 0.05 | J12: 26 | K12: 79 | L12: =FORECAST(J12,$K$5:$K$19,$J$5:$J$19) -> 69.387211 | M12: =K12-L12 -> 9.6127893 | T12: 26 | U12: 79 | V12: =FORECAST(T12,$K$5:$K$19,$J$5:$J$19) -> 69.387211 | W12: =(U12-$U$22)^2 -> 29.884444 | X12: =(V12-$U$22)^2 -> 17.190333 | Y12: =(U12-V12)^2 -> 92.405719
A13: 19 | B13: 75 | D13: F-crit | E13: =FINV(E12,F8,F9) -> 4.6671927 | G13: =FINV(E12,F8,F9) | J13: 11 | K13: 81 | L13: =FORECAST(J13,$K$5:$K$19,$J$5:$J$19) -> 78.810217 | M13: =K13-L13 -> 2.1897833 | T13: 11 | U13: 81 | V13: =FORECAST(T13,$K$5:$K$19,$J$5:$J$19) -> 78.810217 | W13: =(U13-$U$22)^2 -> 55.751111 | X13: =(V13-$U$22)^2 -> 27.845498 | Y13: =(U13-V13)^2 -> 4.7951507
A14: 14 | B14: 68 | D14: p-value | E14: =FDIST(E11,F8,F9) -> 0.002822343 | G14: =FDIST(E11,F8,F9) | J14: 19 | K14: 75 | L14: =FORECAST(J14,$K$5:$K$19,$J$5:$J$19) -> 73.784613 | M14: =K14-L14 -> 1.2153865 | T14: 19 | U14: 75 | V14: =FORECAST(T14,$K$5:$K$19,$J$5:$J$19) -> 73.784613 | W14: =(U14-$U$22)^2 -> 2.1511111 | X14: =(V14-$U$22)^2 -> 0.06314172 | Y14: =(U14-V14)^2 -> 1.4771644
A15: 35 | B15: 72 | D15: sig | E15: =IF(E14<E12,"yes","no") -> yes | G15: =IF(E14<E12,"yes","no") | J15: 14 | K15: 68 | L15: =FORECAST(J15,$K$5:$K$19,$J$5:$J$19) -> 76.925616 | M15: =K15-L15 -> -8.9256155 | T15: 14 | U15: 68 | V15: =FORECAST(T15,$K$5:$K$19,$J$5:$J$19) -> 76.925616 | W15: =(U15-$U$22)^2 -> 30.617778 | X15: =(V15-$U$22)^2 -> 11.507578 | Y15: =(U15-V15)^2 -> 79.666612
A16: 29 | B16: 58 | J16: 35 | K16: 72 | L16: =FORECAST(J16,$K$5:$K$19,$J$5:$J$19) -> 63.733407 | M16: =K16-L16 -> 8.266593 | T16: 35 | U16: 72 | V16: =FORECAST(T16,$K$5:$K$19,$J$5:$J$19) -> 63.733407 | W16: =(U16-$U$22)^2 -> 2.3511111 | X16: =(V16-$U$22)^2 -> 96.038556 | Y16: =(U16-V16)^2 -> 68.33656
A17: 4 | B17: 92 | J17: 29 | K17: 58 | L17: =FORECAST(J17,$K$5:$K$19,$J$5:$J$19) -> 67.502609 | M17: =K17-L17 -> -9.5026094 | T17: 29 | U17: 58 | V17: =FORECAST(T17,$K$5:$K$19,$J$5:$J$19) -> 67.502609 | W17: =(U17-$U$22)^2 -> 241.28444 | X17: =(V17-$U$22)^2 -> 36.369631 | Y17: =(U17-V17)^2 -> 90.299586
A18: 23 | B18: 65 | J18: 4 | K18: 92 | L18: =FORECAST(J18,$K$5:$K$19,$J$5:$J$19) -> 83.20762 | M18: =K18-L18 -> 8.7923804 | T18: 4 | U18: 92 | V18: =FORECAST(T18,$K$5:$K$19,$J$5:$J$19) -> 83.20762 | W18: =(U18-$U$22)^2 -> 341.01778 | X18: =(V18-$U$22)^2 -> 93.591814 | Y18: =(U18-V18)^2 -> 77.305954
J19: 23 | K19: 65 | L19: =FORECAST(J19,$K$5:$K$19,$J$5:$J$19) -> 71.271812 | M19: =K19-L19 -> -6.2718119 | T19: 23 | U19: 65 | V19: =FORECAST(T19,$K$5:$K$19,$J$5:$J$19) -> 71.271812 | W19: =(U19-$U$22)^2 -> 72.817778 | X19: =(V19-$U$22)^2 -> 5.1144793 | Y19: =(U19-V19)^2 -> 39.335624
W20: =SUM(W5:W19) -> 1683.7333 | X20: =SUM(X5:X19) -> 856.99099 | Y20: =SUM(Y5:Y19) -> 826.74234
J21: mean | K21: =AVERAGE(K5:K19) -> 73.533333 | L21: =AVERAGE(L5:L19) -> 73.533333 | M21: =AVERAGE(M5:M19) -> 6.6317322e-15 | T21: n | U21: =COUNT(T5:T19) -> 15
J22: std dev | K22: =STDEV(K5:K19) -> 10.966616 | L22: =STDEV(L5:L19) -> 7.8239148 | M22: =STDEV(M5:M19) -> 7.6845966 | T22: mean y | U22: =AVERAGE(U5:U19) -> 73.533333

Sheet Reg 3
A1: Test the slope of the regression line
A3: Cig (x) | B3: Life Exp (y) | D3: n | E3: =COUNT(A4:A18) -> 15 | G3: =COUNT(A4:A18) | I3: n | J3: =COUNT(A4:A18) -> 15 | L3: =COUNT(A4:A18)
A4: 5 | B4: 80 | D4: r | E4: =CORREL(A4:A18,B4:B18) -> -0.71343017 | G4: =CORREL(A4:A18,B4:B18) | I4: sx | J4: =STDEV(A4:A18) -> 12.454489 | L4: =STDEV(A4:A18)
A5: 23 | B5: 78 | D5: sx | E5: =STDEV(A4:A18) -> 12.454489 | G5: =STDEV(A4:A18) | I5: b | J5: =SLOPE(B4:B18,A4:A18) -> -0.62820041 | L5: =SLOPE(B4:B18,A4:A18)
A6: 25 | B6: 60 | D6: sy | E6: =STDEV(B4:B18) -> 10.966616 | G6: =STDEV(B4:B18) | I6: sy∙x | J6: =STEYX(B4:B18,A4:A18) -> 7.9746827 | L6: =STEYX(B4:B18,A4:A18)
A7: 48 | B7: 53 | D7: b | E7: =E4*E6/E5 -> -0.62820041 | G7: =E4*E6/E5 | I7: sb | J7: =J6/(J4*SQRT(J3-1)) -> 0.17112895 | L7: =J6/(J4*SQRT(J3-1))
A8: 17 | B8: 85 | D8: sy∙x | E8: =E6*SQRT((1-E4^2)*(E3-1)/(E3-2)) -> 7.9746827 | G8: =E6*SQRT((1-E4^2)*(E3-1)/(E3-2)) | I8: t | J8: =J5/J7 -> -3.6709183 | L8: =J5/J7
A9: 8 | B9: 84 | D9: sb | E9: =E8/(E5*SQRT(E3-1)) -> 0.17112895 | G9: =E8/(E5*SQRT(E3-1)) | I9: df | J9: =J3-2 -> 13 | L9: =J3-2
A10: 4 | B10: 73 | D10: t | E10: =E7/E9 -> -3.6709183 | G10: =E7/E9 | I10: p-value | J10: =TDIST(ABS(J8),J9,2) -> 0.002822343 | L10: =TDIST(ABS(J8),J9,2)
A11: 26 | B11: 79 | D11: df | E11: =E3-2 -> 13 | G11: =E3-2 | I11: alpha | J11: 0.05
A12: 11 | B12: 81 | D12: p-value | E12: =TDIST(ABS(E10),E11,2) -> 0.002822343 | G12: =TDIST(ABS(E10),E11,2) | I12: t-crit | J12: =TINV(0.05,J9) -> 2.1603687 | L12: =TINV(0.05,J9)
A13: 19 | B13: 75 | D13: alpha | E13: 0.05 | I13: sig | J13: =IF(J10<J11,"yes","no") -> yes | L13: =IF(J10<J11,"yes","no")
A14: 14 | B14: 68 | D14: t-crit | E14: =TINV(0.05,E11) -> 2.1603687 | G14: =TINV(0.05,E11)
A15: 35 | B15: 72 | D15: sig | E15: =IF(E12<E13,"yes","no") -> yes | G15: =IF(E12<E13,"yes","no") | I15: Confidence interval
A16: 29 | B16: 58
A17: 4 | B17: 92 | D17: Confidence interval | I17: lower | J17: =J5-J12*J7 -> -0.99790203 | L17: =J5-J12*J7
A18: 23 | B18: 65 | I18: upper | J18: =J5+J12*J7 -> -0.25849878 | L18: =J5+J12*J7
D19: lower | E19: =E7-E14*E9 -> -0.99790203 | G19: =E7-E14*E9
D20: upper | E20: =E7+E14*E9 -> -0.25849878 | G20: =E7+E14*E9

Sheet Reg 4
A1: SUMMARY OUTPUT
R2: RESIDUAL OUTPUT | W2: PROBABILITY OUTPUT
A3: Regression Statistics
A4: Multiple R | B4: 0.71343017 | R4: Observation | S4: Predicted Life Exp | T4: Residuals | U4: Standard Residuals | W4: Percentile | X4: Life Exp
A5: R Square | B5: 0.50898261 | R5: 1 | S5: 82.579419 | T5: -2.5794192 | U5: -0.33566097 | W5: 3.3333333 | X5: 53
A6: Adjusted R Square | B6: 0.47121205 | R6: 2 | S6: 71.271812 | T6: 6.7281881 | U6: 0.87554214 | W6: 10 | X6: 58
A7: Standard Error | B7: 7.9746827 | R7: 3 | S7: 70.015411 | T7: -10.015411 | U7: -1.3033099 | W7: 16.666667 | X7: 60
A8: Observations | B8: 15 | R8: 4 | S8: 55.566802 | T8: -2.5668017 | U8: -0.33401906 | W8: 23.333333 | X8: 65
R9: 5 | S9: 75.041014 | T9: 9.9589857 | U9: 1.2959673 | W9: 30 | X9: 68
A10: ANOVA | R10: 6 | S10: 80.694818 | T10: 3.305182 | U10: 0.43010482 | W10: 36.666667 | X10: 72
B11: df | C11: SS | D11: MS | E11: F | F11: Significance F | R11: 7 | S11: 83.20762 | T11: -10.20762 | U11: -1.3283221 | W11: 43.333333 | X11: 73
A12: Regression | B12: 1 | C12: 856.99099 | D12: 856.99099 | E12: 13.475641 | F12: 0.002822343 | R12: 8 | S12: 69.387211 | T12: 9.6127893 | U12: 1.2509166 | W12: 50 | X12: 75
A13: Residual | B13: 13 | C13: 826.74234 | D13: 63.595565 | R13: 9 | S13: 78.810217 | T13: 2.1897833 | U13: 0.28495748 | W13: 56.666667 | X13: 78
A14: Total | B14: 14 | C14: 1683.7333 | R14: 10 | S14: 73.784613 | T14: 1.2153865 | U14: 0.15815879 | W14: 63.333333 | X14: 79
R15: 11 | S15: 76.925616 | T15: -8.9256155 | U15: -1.1614944 | W15: 70 | X15: 80
B16: Coefficients | C16: Standard Error | D16: t Stat | E16: P-value | F16: Lower 95% | G16: Upper 95% | R16: 12 | S16: 63.733407 | T16: 8.266593 | U16: 1.0757355 | W16: 76.666667 | X16: 81
A17: Intercept | B17: 85.720421 | C17: 3.9065908 | D17: 21.942513 | E17: 1.1757939e-11 | F17: 77.280745 | G17: 94.160098 | R17: 13 | S17: 67.502609 | T17: -9.5026094 | U17: -1.2365788 | W17: 83.333333 | X17: 84
A18: Cig (x) | B18: -0.62820041 | C18: 0.17112895 | D18: -3.6709183 | E18: 0.002822343 | F18: -0.99790203 | G18: -0.25849878 | R18: 14 | S18: 83.20762 | T18: 8.7923804 | U18: 1.1441564 | W18: 90 | X18: 85
R19: 15 | S19: 71.271812 | T19: -6.2718119 | U19: -0.81615369 | W19: 96.666667 | X19: 92

Sheet Reg 5
A1: Testing two slopes | M1: Comparison of two slopes
A3: Men | D3: Women | N3: Men | O3: Women
A4: Cig (x) | B4: Life Exp (y) | D4: Cig (x) | E4: Life Exp (y) | M4: n | N4: =COUNT(A5:A19) -> 15 | O4: =COUNT(D5:D20) -> 16 | Q4: =COUNT(x)
A5: 5 | B5: 80 | D5: 22 | E5: 88 | M5: b | N5: =SLOPE(B5:B19,A5:A19) -> -0.62820041 | O5: =SLOPE(E5:E20,D5:D20) -> -0.46785962 | Q5: =SLOPE(y,x)
A6: 23 | B6: 78 | D6: 7 | E6: 95 | M6: sy∙x | N6: =STEYX(B5:B19,A5:A19) -> 7.9746827 | O6: =STEYX(E5:E20,D5:D20) -> 8.3792453 | Q6: =STEYX(y,x)
A7: 25 | B7: 60 | D7: 20 | E7: 86 | M7: sx | N7: =STDEV(A5:A19) -> 12.454489 | O7: =STDEV(D5:D20) -> 13.851594 | Q7: =STDEV(x)
A8: 48 | B8: 53 | D8: 23 | E8: 60 | M8: sb | N8: =N6/(N7*SQRT(N4-1)) -> 0.17112895 | O8: =O6/(O7*SQRT(O4-1)) -> 0.15619226 | Q8: = sy∙x / (sx * SQRT(n-1)) | S8: Using pooled error variance
A9: 17 | B9: 85 | D9: 15 | E9: 82 | S9: sRes2 | T9: =((N4-2)*N6^2+(O4-2)*O6^2)/(N4+O4-4) -> 67.02618 | V9: = ((n1-2)sy.x12+(n2-2)sy.x22)/(n1+n2-4)
A10: 8 | B10: 84 | D10: 34 | E10: 75 | M10: sb1-b2 | N10: =SQRT(N8^2+O8^2) -> 0.23169191 | Q10: = SQRT(sb12+sb22) | S10: sb1-b2 | T10: =SQRT(T9*(1/(N7^2*(N4-1))+1/(O7^2*(O4-1)))) -> 0.2327102 | V10: = sRes*SQRT(1/(sx12(n1-1))+1/(sx22(n2-1)))
A11: 4 | B11: 73 | D11: 4 | E11: 80 | M11: t | N11: =(N5-O5)/N10 -> -0.69204307 | Q11: = (b1-b2)/(sb1-b2) | S11: t | T11: =(N5-O5)/T10 -> -0.68901485 | V11: = (b1-b2)/(sb1-b2)
A12: 26 | B12: 79 | D12: 40 | E12: 68 | M12: df | N12: =N4+O4-4 -> 27 | Q12: = n1+n2-4 | S12: df | T12: =N4+O4-4 -> 27 | V12: = n1+n2-4
A13: 11 | B13: 81 | D13: 8 | E13: 93 | M13: alpha | N13: 0.05 | S13: alpha | T13: 0.05
A14: 19 | B14: 75 | D14: 16 | E14: 77 | M14: p-value | N14: =TDIST(ABS(N11),N12,2) -> 0.49481917 | Q14: = TDIST(|t|,df,2) | S14: p-value | T14: =TDIST(ABS(T11),T12,2) -> 0.49669273 | V14: = TDIST(|t|,df,2)
A15: 14 | B15: 68 | D15: 11 | E15: 72 | M15: t-crit | N15: =TINV(N13,N12) -> 2.0518305 | Q15: = TINV(α,df) | S15: t-crit | T15: =TINV(T13,T12) -> 2.0518305 | V15: = TINV(α,df)
A16: 35 | B16: 72 | D16: 52 | E16: 67 | M16: sig | N16: =IF(ABS(N11)<N15,"no","yes") -> no | Q16: = yes if p-value < α | S16: sig | T16: =IF(ABS(T11)<T15,"no","yes") -> no | V16: = yes if p-value < α
A17: 29 | B17: 58 | D17: 3 | E17: 90
A18: 4 | B18: 92 | D18: 31 | E18: 66
A19: 23 | B19: 65 | D19: 18 | E19: 72 | M19: Using Real Statistics functions
D20: 8 | E20: 78
M21: sb1-b2 | N21: {=SlopesTest(A5:A19,B5:B19,D5:D20,E5:E20,FALSE)} -> #NAME? | S21: sb1-b2 | T21: {=SlopesTest(A5:A19,B5:B19,D5:D20,E5:E20)} -> #NAME?
M22: t | N22: #NAME? | S22: t | T22: #NAME?
M23: df | N23: #NAME? | S23: df | T23: #NAME?
M24: p-value | N24: #NAME? | S24: p-value | T24: #NAME?
M26: Using Real Statistics functions
M27: with and w/o labels
N29: no pool | O29: pooled
M30: {=SlopesTest(A5:A19,B5:B19,D5:D20,E5:E20,FALSE,TRUE)} -> #NAME? | N30: #NAME? | O30: {=SlopesTest(A5:A19,B5:B19,D5:D20,E5:E20)} -> #NAME?
M31: #NAME? | N31: #NAME? | O31: #NAME?
M32: #NAME? | N32: #NAME? | O32: #NAME?
M33: #NAME? | N33: #NAME? | O33: #NAME?

Sheet Reg 6
A1: Confidence and Prediction Intervals
A3: Cig (x) | B3: Life Exp (y) | D3: Confidence interval for the forecasted value
A4: 5 | B4: 80
A5: 23 | B5: 78 | D5: n | E5: =COUNT(A4:A18) -> 15
A6: 25 | B6: 60 | D6: df | E6: =E5-2 -> 13 | G6: = n - 2
A7: 48 | B7: 53 | D7: mean(x) | E7: =AVERAGE(A4:A18) -> 19.4 | G7: = AVERAGE(x)
A8: 17 | B8: 85 | D8: x0 | E8: 20
A9: 8 | B9: 84 | D9: ŷ0 | E9: =FORECAST(E8,B4:B18,A4:A18) -> 73.156413 | G9: = FORECAST(y,x,x0) | I9: Prediction interval | L9: Test for y-intercept
A10: 4 | B10: 73 | D10: sRes | E10: =STEYX(B4:B18,A4:A18) -> 7.9746827 | G10: = STEYX(y,x)
A11: 26 | B11: 79 | D11: SSx | E11: =DEVSQ(A4:A18) -> 2171.6 | G11: = DEVSQ(x) | I11: ŷ0 | J11: =E9 -> 73.156413 | L11: ŷ0 | M11: =FORECAST(0,B4:B18,A4:A18) -> 85.720421
A12: 11 | B12: 81 | D12: se | E12: =E10*SQRT(1/E5+(E8-E7)^2/E11) -> 2.0616127 | G12: = sRes*SQRT(1/n+(x0-x̄)^2/SSx) | I12: se | J12: =E10*SQRT(1+1/E5+(E8-E7)^2/E11) -> 8.2368569 | L12: se | M12: =E10*SQRT(1/E5+E7^2/E11) -> 3.9065908
A13: 19 | B13: 75 | D13: t-crit | E13: =TINV(0.05,E6) -> 2.1603687 | G13: = TINV(0.05,df) | I13: t-crit | J13: =TINV(0.05,E6) -> 2.1603687 | L13: t-crit | M13: =E13 -> 2.1603687
A14: 14 | B14: 68 | D14: lower | E14: =E9-E13*E12 -> 68.70257 | G14: = ŷ0 - t-crit * se | I14: lower | J14: =J11-J13*J12 -> 55.361766 | L14: lower | M14: =M11-M13*M12 -> 77.280745
A15: 35 | B15: 72 | D15: upper | E15: =E9+E13*E12 -> 77.610257 | G15: = ŷ0 + t-crit * se | I15: upper | J15: =J11+J13*J12 -> 90.951061 | L15: upper | M15: =M11+M13*M12 -> 94.160098
A16: 29 | B16: 58
A17: 4 | B17: 92
A18: 23 | B18: 65

Sheet Reg 7
A1: Confidence and Prediction Intervals
A3: Cig (x) | B3: Life Exp (y) | D3: alpha | E3: 0.05 | G3: x | H3: y | I3: lower | J3: upper | K3: conf se | L3: pred | M3: lower | N3: upper | O3: pred se
A4: 5 | B4: 80 | D4: n | E4: =COUNT(A4:A18) -> 15 | G4: 0 | H4: {=TREND(B4:B18,A4:A18,G4:G14)} -> 85.720421 | I4: =H4-$E$8*K4 -> 77.280745 | J4: =H4+$E$8*K4 -> 94.160098 | K4: =$E$7*SQRT(1/$E$4+(G4-$E$5)^2/$E$6) -> 3.9065908 | L4: =H4 -> 85.720421 | M4: =L4-$E$8*O4 -> 66.536029 | N4: =L4+$E$8*O4 -> 104.90481 | O4: =$E$7*SQRT(1+1/$E$4+(G4-$E$5)^2/$E$6) -> 8.8801473
A5: 23 | B5: 78 | D5: mean(x) | E5: =AVERAGE(A4:A18) -> 19.4 | G5: =G4+5 -> 5 | H5: 82.579419 | I5: =H5-$E$8*K5 -> 75.641888 | J5: =H5+$E$8*K5 -> 89.51695 | K5: =$E$7*SQRT(1/$E$4+(G5-$E$5)^2/$E$6) -> 3.2112718 | L5: =H5 -> 82.579419 | M5: =L5-$E$8*O5 -> 64.006802 | N5: =L5+$E$8*O5 -> 101.15204 | O5: =$E$7*SQRT(1+1/$E$4+(G5-$E$5)^2/$E$6) -> 8.5969664
A6: 25 | B6: 60 | D6: devsq(x) | E6: =DEVSQ(A4:A18) -> 2171.6 | G6: =G5+5 -> 10 | H6: 79.438417 | I6: =H6-$E$8*K6 -> 73.793552 | J6: =H6+$E$8*K6 -> 85.083282 | K6: =$E$7*SQRT(1/$E$4+(G6-$E$5)^2/$E$6) -> 2.6129174 | L6: =H6 -> 79.438417 | M6: =L6-$E$8*O6 -> 61.308959 | N6: =L6+$E$8*O6 -> 97.567875 | O6: =$E$7*SQRT(1+1/$E$4+(G6-$E$5)^2/$E$6) -> 8.3918354
A7: 48 | B7: 53 | D7: steyx | E7: =STEYX(B4:B18,A4:A18) -> 7.9746827 | G7: =G6+5 -> 15 | H7: 76.297415 | I7: =H7-$E$8*K7 -> 71.561 | J7: =H7+$E$8*K7 -> 81.03383 | K7: =$E$7*SQRT(1/$E$4+(G7-$E$5)^2/$E$6) -> 2.1924106 | L7: =H7 -> 76.297415 | M7: =L7-$E$8*O7 -> 58.429948 | N7: =L7+$E$8*O7 -> 94.164882 | O7: =$E$7*SQRT(1+1/$E$4+(G7-$E$5)^2/$E$6) -> 8.270564
A8: 17 | B8: 85 | D8: t-crit | E8: =TINV(E3,E4-2) -> 2.1603687 | G8: =G7+5 -> 20 | H8: 73.156413 | I8: =H8-$E$8*K8 -> 68.70257 | J8: =H8+$E$8*K8 -> 77.610257 | K8: =$E$7*SQRT(1/$E$4+(G8-$E$5)^2/$E$6) -> 2.0616127 | L8: =H8 -> 73.156413 | M8: =L8-$E$8*O8 -> 55.361766 | N8: =L8+$E$8*O8 -> 90.951061 | O8: =$E$7*SQRT(1+1/$E$4+(G8-$E$5)^2/$E$6) -> 8.2368569
A9: 8 | B9: 84 | G9: =G8+5 -> 25 | H9: 70.015411 | I9: =H9-$E$8*K9 -> 65.108907 | J9: =H9+$E$8*K9 -> 74.921915 | K9: =$E$7*SQRT(1/$E$4+(G9-$E$5)^2/$E$6) -> 2.2711419 | L9: =H9 -> 70.015411 | M9: =L9-$E$8*O9 -> 52.102105 | N9: =L9+$E$8*O9 -> 87.928717 | O9: =$E$7*SQRT(1+1/$E$4+(G9-$E$5)^2/$E$6) -> 8.2917821
A10: 4 | B10: 73 | G10: =G9+5 -> 30 | H10: 66.874409 | I10: =H10-$E$8*K10 -> 60.946104 | J10: =H10+$E$8*K10 -> 72.802714 | K10: =$E$7*SQRT(1/$E$4+(G10-$E$5)^2/$E$6) -> 2.7441174 | L10: =H10 -> 66.874409 | M10: =L10-$E$8*O10 -> 48.654707 | N10: =L10+$E$8*O10 -> 85.094112 | O10: =$E$7*SQRT(1+1/$E$4+(G10-$E$5)^2/$E$6) -> 8.4336081
A11: 26 | B11: 79 | G11: =G10+5 -> 35 | H11: 63.733407 | I11: =H11-$E$8*K11 -> 56.449878 | J11: =H11+$E$8*K11 -> 71.016936 | K11: =$E$7*SQRT(1/$E$4+(G11-$E$5)^2/$E$6) -> 3.3714286 | L11: =H11 -> 63.733407 | M11: =L11-$E$8*O11 -> 45.028794 | N11: =L11+$E$8*O11 -> 82.43802 | O11: =$E$7*SQRT(1+1/$E$4+(G11-$E$5)^2/$E$6) -> 8.6580653
A12: 11 | B12: 81 | G12: =G11+5 -> 40 | H12: 60.592405 | I12: =H12-$E$8*K12 -> 51.772612 | J12: =H12+$E$8*K12 -> 69.412198 | K12: =$E$7*SQRT(1/$E$4+(G12-$E$5)^2/$E$6) -> 4.0825406 | L12: =H12 -> 60.592405 | M12: =L12-$E$8*O12 -> 41.23778 | N12: =L12+$E$8*O12 -> 79.94703 | O12: =$E$7*SQRT(1+1/$E$4+(G12-$E$5)^2/$E$6) -> 8.9589454
A13: 19 | B13: 75 | G13: =G12+5 -> 45 | H13: 57.451403 | I13: =H13-$E$8*K13 -> 46.99379 | J13: =H13+$E$8*K13 -> 67.909015 | K13: =$E$7*SQRT(1/$E$4+(G13-$E$5)^2/$E$6) -> 4.8406611 | L13: =H13 -> 57.451403 | M13: =L13-$E$8*O13 -> 37.297634 | N13: =L13+$E$8*O13 -> 77.605172 | O13: =$E$7*SQRT(1+1/$E$4+(G13-$E$5)^2/$E$6) -> 9.3288566
A14: 14 | B14: 68 | G14: =G13+5 -> 50 | H14: 54.310401 | I14: =H14-$E$8*K14 -> 42.154392 | J14: =H14+$E$8*K14 -> 66.466409 | K14: =$E$7*SQRT(1/$E$4+(G14-$E$5)^2/$E$6) -> 5.6268213 | L14: =H14 -> 54.310401 | M14: =L14-$E$8*O14 -> 33.225304 | N14: =L14+$E$8*O14 -> 75.395498 | O14: =$E$7*SQRT(1+1/$E$4+(G14-$E$5)^2/$E$6) -> 9.759953
A15: 35 | B15: 72
A16: 29 | B16: 58
A17: 4 | B17: 92
A18: 23 | B18: 65

Sheet Exp Reg
A1: Exponential Regression
A3: Original Data | D3: Log Transformed Data | G3: SUMMARY OUTPUT | O3: Use of LOGEST
A5: x | B5: y | D5: x | E5: ln y | G5: Regression Statistics | O5: Slope: Exp(b) | P5: {=LOGEST(B6:B16,A6:A16,TRUE,TRUE)} -> 1.0162211 | Q5: 14.051352 | R5: Intercept: Exp(a)
A6: 45 | B6: 33 | D6: =A6 -> 45 | E6: =LN(B6) -> 3.4965076 | G6: Multiple R | H6: 0.93894243 | O6: S.E. of slope | P6: 0.0019655063 | Q6: 0.12108366 | R6: S.E. of intercept (sa)
A7: 99 | B7: 72 | D7: =A7 -> 99 | E7: =LN(B7) -> 4.2766661 | G7: R Square | H7: 0.88161289 | O7: R-Squared | P7: 0.88161289 | Q7: 0.1866582 | R7: S.E. of estimate (sRes)
A8: 31 | B8: 19 | D8: =A8 -> 31 | E8: =LN(B8) -> 2.944439 | G8: Adjusted R Square | H8: 0.86845877 | O8: F | P8: 67.021793 | Q8: 9 | R8: dfRes
A9: 57 | B9: 27 | D9: =A9 -> 57 | E9: =LN(B9) -> 3.2958369 | G9: Standard Error | H9: 0.1866582 | O9: SSReg | P9: 2.3351253 | Q9: 0.31357155 | R9: SSRes
A10: 37 | B10: 23 | D10: =A10 -> 37 | E10: =LN(B10) -> 3.1354942 | G10: Observations | H10: 11
A11: 85 | B11: 62 | D11: =A11 -> 85 | E11: =LN(B11) -> 4.1271344
A12: 21 | B12: 24 | D12: =A12 -> 21 | E12: =LN(B12) -> 3.1780538 | G12: ANOVA | O12: Use of GROWTH
A13: 64 | B13: 32 | D13: =A13 -> 64 | E13: =LN(B13) -> 3.4657359 | H13: df | I13: SS | J13: MS | K13: F | L13: Significance F
A14: 17 | B14: 18 | D14: =A14 -> 17 | E14: =LN(B14) -> 2.8903718 | G14: Regression | H14: 1 | I14: 2.3351253 | J14: 2.3351253 | K14: 67.021793 | L14: 1.8400739e-05 | O14: x | P14: y
A15: 41 | B15: 36 | D15: =A15 -> 41 | E15: =LN(B15) -> 3.5835189 | G15: Residual | H15: 9 | I15: 0.31357155 | J15: 0.034841284 | O15: 25 | P15: {=GROWTH(B6:B16,A6:A16,O15:O16)} -> 21.009886
A16: 103 | B16: 76 | D16: =A16 -> 103 | E16: =LN(B16) -> 4.3307333 | G16: Total | H16: 10 | I16: 2.6486968 | O16: 35 | P16: 24.67777
H18: Coefficients | I18: Standard Error | J18: t Stat | K18: P-value | L18: Lower 95% | M18: Upper 95% | O18: Use of slope and intercept for prediction
A19: r | B19: =CORREL(E6:E16,D6:D16) -> 0.93894243 | G19: Intercept | H19: 2.6427186 | I19: 0.12108366 | J19: 21.825559 | K19: 4.1968546e-09 | L19: 2.3688083 | M19: 2.9166289
G20: x | H20: 0.016090979 | I20: 0.0019655063 | J20: 8.1866839 | K20: 1.8400739e-05 | L20: 0.011644695 | M20: 0.020537263 | O20: x | P20: y
O21: 25 | P21: =Q5*P5^O21 -> 21.009886
G22: ea | H22: =EXP(H19) -> 14.051352 | J22: x | K22: 26 | O22: 35 | P22: =Q5*P5^O22 -> 24.67777
G23: eb | H23: =EXP(H20) -> 1.0162211 | J23: y | K23: =H22*H23^K22 -> 21.35069
O24: Use of TREND
O26: x | P26: y
O27: 25 | P27: {=EXP(TREND(LN(B6:B16),A6:A16,O15:O16))} -> 21.009886
O28: 35 | P28: 24.67777

Sheet Exp Reg1
A1: Exponential Regression
A3: x | B3: y | C3: pred y | D3: residual | E3: resid-sq
A4: 45 | B4: 33 | C4: =$B$16*EXP($B$17*A4) -> 28.985991 | D4: =B4-C4 -> 4.0140089 | E4: =D4^2 -> 16.112268
A5: 99 | B5: 72 | C5: =$B$16*EXP($B$17*A5) -> 69.111802 | D5: =B5-C5 -> 2.8881982 | E5: =D5^2 -> 8.341689
A6: 31 | B6: 19 | C6: =$B$16*EXP($B$17*A6) -> 23.13945 | D6: =B6-C6 -> -4.1394497 | E6: =D6^2 -> 17.135044
A7: 57 | B7: 27 | C7: =$B$16*EXP($B$17*A7) -> 35.159835 | D7: =B7-C7 -> -8.1598355 | E7: =D7^2 -> 66.582915
A8: 37 | B8: 23 | C8: =$B$16*EXP($B$17*A8) -> 25.484867 | D8: =B8-C8 -> -2.4848667 | E8: =D8^2 -> 6.1745627
A9: 85 | B9: 62 | C9: =$B$16*EXP($B$17*A9) -> 55.171792 | D9: =B9-C9 -> 6.8282083 | E9: =D9^2 -> 46.624428
A10: 21 | B10: 24 | C10: =$B$16*EXP($B$17*A10) -> 19.700207 | D10: =B10-C10 -> 4.2997928 | E10: =D10^2 -> 18.488218
A11: 64 | B11: 32 | C11: =$B$16*EXP($B$17*A11) -> 39.351781 | D11: =B11-C11 -> -7.3517815 | E11: =D11^2 -> 54.048691
A12: 17 | B12: 18 | C12: =$B$16*EXP($B$17*A12) -> 18.472169 | D12: =B12-C12 -> -0.47216928 | E12: =D12^2 -> 0.22294383
A13: 41 | B13: 36 | C13: =$B$16*EXP($B$17*A13) -> 27.179112 | D13: =B13-C13 -> 8.8208882 | E13: =D13^2 -> 77.808068
A14: 103 | B14: 76 | C14: =$B$16*EXP($B$17*A14) -> 73.706385 | D14: =B14-C14 -> 2.2936154 | E14: =D14^2 -> 5.2606718
E15: =SUM(E4:E14) -> 316.7995
A16: α | B16: 14.051352
A17: β | B17: 0.016090979

Sheet Exp Reg2
A1: Exponential Regression
A3: x | B3: y | C3: pred y | D3: residual | E3: resid-sq
A4: 45 | B4: 33 | C4: =$B$16*EXP($B$17*A4) -> 28.83166 | D4: =B4-C4 -> 4.1683403 | E4: =D4^2 -> 17.375061
A5: 99 | B5: 72 | C5: =$B$16*EXP($B$17*A5) -> 71.635683 | D5: =B5-C5 -> 0.36431709 | E5: =D5^2 -> 0.13272694
A6: 31 | B6: 19 | C6: =$B$16*EXP($B$17*A6) -> 22.77167 | D6: =B6-C6 -> -3.7716705 | E6: =D6^2 -> 14.225498
A7: 57 | B7: 27 | C7: =$B$16*EXP($B$17*A7) -> 35.294347 | D7: =B7-C7 -> -8.2943466 | E7: =D7^2 -> 68.796186
A8: 37 | B8: 23 | C8: =$B$16*EXP($B$17*A8) -> 25.1949 | D8: =B8-C8 -> -2.1949002 | E8: =D8^2 -> 4.8175868
A9: 85 | B9: 62 | C9: =$B$16*EXP($B$17*A9) -> 56.57892 | D9: =B9-C9 -> 5.4210801 | E9: =D9^2 -> 29.38811
A10: 21 | B10: 24 | C10: =$B$16*EXP($B$17*A10) -> 19.239715 | D10: =B10-C10 -> 4.7602848 | E10: =D10^2 -> 22.660312
A11: 64 | B11: 32 | C11: =$B$16*EXP($B$17*A11) -> 39.713899 | D11: =B11-C11 -> -7.7138986 | E11: =D11^2 -> 59.504232
A12: 17 | B12: 18 | C12: =$B$16*EXP($B$17*A12) -> 17.985402 | D12: =B12-C12 -> 0.014598485 | E12: =D12^2 -> 0.00021311576
A13: 41 | B13: 36 | C13: =$B$16*EXP($B$17*A13) -> 26.952009 | D13: =B13-C13 -> 9.047991 | E13: =D13^2 -> 81.866141
A14: 103 | B14: 76 | C14: =$B$16*EXP($B$17*A14) -> 76.631602 | D14: =B14-C14 -> -0.63160228 | E14: =D14^2 -> 0.39892144
E15: =SUM(E4:E14) -> 299.16499
A16: α | B16: 13.504749
A17: β | B17: 0.01685406

Sheet Exp Reg3
A1: Exponential Regression
A3: x | B3: y | D3: Exp(bx) | E3: F1 | F3: F2 | G3: J11 | H3: J12 | I3: J22 | K3: pred-y | L3: resid-sq
A4: 45 | B4: 33 | D4: =EXP($B$20*A4) -> 2.0628614 | E4: =(B4-$B$19*D4)*D4 -> 8.2803441 | F4: =E4*A4*$B$19 -> 5235.7512 | G4: =-(D4^2) -> -4.2553972 | H4: =(B4-2*$B$19*D4)*D4*A4 -> -2318.1182 | I4: =H4*$B$19*A4 -> -1465771.2 | K4: =$B$31*EXP($B$32*A4) -> 28.831681 | L4: =(B4-K4)^2 -> 17.374887
A5: 99 | B5: 72 | D5: =EXP($B$20*A5) -> 4.9185163 | E5: =(B5-$B$19*D5)*D5 -> 14.20565 | F5: =E5*A5*$B$19 -> 19761.25 | G5: =-(D5^2) -> -24.191802 | H5: =(B5-2*$B$19*D5)*D5*A5 -> -32246.465 | I5: =H5*$B$19*A5 -> -44857536 | K5: =$B$31*EXP($B$32*A5) -> 71.635797 | L5: =(B5-K5)^2 -> 0.13264377
A6: 31 | B6: 19 | D6: =EXP($B$20*A6) -> 1.6467775 | E6: =(B6-$B$19*D6)*D6 -> -6.8167527 | F6: =E6*A6*$B$19 -> -2969.3222 | G6: =-(D6^2) -> -2.7118761 | H6: =(B6-2*$B$19*D6)*D6*A6 -> -1392.5906 | I6: =H6*$B$19*A6 -> -606601.19 | K6: =$B$31*EXP($B$32*A6) -> 22.771682 | L6: =(B6-K6)^2 -> 14.225584
A7: 57 | B7: 27 | D7: =EXP($B$20*A7) -> 2.5022387 | E7: =(B7-$B$19*D7)*D7 -> -20.417856 | F7: =E7*A7*$B$19 -> -16353.213 | G7: =-(D7^2) -> -6.2611984 | H7: =(B7-2*$B$19*D7)*D7*A7 -> -6178.5809 | I7: =H7*$B$19*A7 -> -4948592.5 | K7: =$B$31*EXP($B$32*A7) -> 35.294379 | L7: =(B7-K7)^2 -> 68.796723
A8: 37 | B8: 23 | D8: =EXP($B$20*A8) -> 1.813695 | E8: =(B8-$B$19*D8)*D8 -> -4.5067905 | F8: =E8*A8*$B$19 -> -2343.0804 | G8: =-(D8^2) -> -3.2894897 | H8: =(B8-2*$B$19*D8)*D8*A8 -> -1876.957 | I8: =H8*$B$19*A8 -> -975829.95 | K8: =$B$31*EXP($B$32*A8) -> 25.194915 | L8: =(B8-K8)^2 -> 4.8176526
A9: 85 | B9: 62 | D9: =EXP($B$20*A9) -> 3.9264402 | E9: =(B9-$B$19*D9)*D9 -> 26.810551 | F9: =E9*A9*$B$19 -> 32021.581 | G9: =-(D9^2) -> -15.416933 | H9: =(B9-2*$B$19*D9)*D9*A9 -> -16134.546 | I9: =H9*$B$19*A9 -> -19270535 | K9: =$B$31*EXP($B$32*A9) -> 56.578997 | L9: =(B9-K9)^2 -> 29.38727
A10: 21 | B10: 24 | D10: =EXP($B$20*A10) -> 1.4020151 | E10: =(B10-$B$19*D10)*D10 -> 6.0283745 | F10: =E10*A10*$B$19 -> 1778.843 | G10: =-(D10^2) -> -1.9656463 | H10: =(B10-2*$B$19*D10)*D10*A10 -> -453.42388 | I10: =H10*$B$19*A10 -> -133795.59 | K10: =$B$31*EXP($B$32*A10) -> 19.239722 | L10: =(B10-K10)^2 -> 22.66025
A11: 64 | B11: 32 | D11: =EXP($B$20*A11) -> 2.8005691 | E11: =(B11-$B$19*D11)*D11 -> -20.589172 | F11: =E11*A11*$B$19 -> -18515.565 | G11: =-(D11^2) -> -7.8431874 | H11: =(B11-2*$B$19*D11)*D11*A11 -> -8370.9796 | I11: =H11*$B$19*A11 -> -7527909 | K11: =$B$31*EXP($B$32*A11) -> 39.71394 | L11: =(B11-K11)^2 -> 59.504863
A12: 17 | B12: 18 | D12: =EXP($B$20*A12) -> 1.3146187 | E12: =(B12-$B$19*D12)*D12 -> -0.62072255 | F12: =E12*A12*$B$19 -> -148.27384 | G12: =-(D12^2) -> -1.7282223 | H12: =(B12-2*$B$19*D12)*D12*A12 -> -423.37788 | I12: =H12*$B$19*A12 -> -101133.54 | K12: =$B$31*EXP($B$32*A12) -> 17.985406 | L12: =(B12-K12)^2 -> 0.00021297252
A13: 41 | B13: 36 | D13: =EXP($B$20*A13) -> 1.9342703 | E13: =(B13-$B$19*D13)*D13 -> 17.061982 | F13: =E13*A13*$B$19 -> 9829.5002 | G13: =-(D13^2) -> -3.7414015 | H13: =(B13-2*$B$19*D13)*D13*A13 -> -1455.9004 | I13: =H13*$B$19*A13 -> -838752.12 | K13: =$B$31*EXP($B$32*A13) -> 26.952027 | L13: =(B13-K13)^2 -> 81.86582
A14: 103 | B14: 76 | D14: =EXP($B$20*A14) -> 5.2455014 | E14: =(B14-$B$19*D14)*D14 -> 12.031163 | F14: =E14*A14*$B$19 -> 17412.572 | G14: =-(D14^2) -> -27.515285 | H14: =(B14-2*$B$19*D14)*D14*A14 -> -38583.365 | I14: =H14*$B$19*A14 -> -55841289 | K14: =$B$31*EXP($B$32*A14) -> 76.631729 | L14: =(B14-K14)^2 -> 0.39908198
E15: =SUM(E4:E14) -> 31.466771 | F15: =SUM(F4:F14) -> 45710.044 | G15: =SUM(G4:G14) -> -98.920438 | H15: =SUM(H4:H14) -> -109434.31 | I15: =SUM(I4:I14) -> -1.3656775e+08 | L15: =SUM(L4:L14) -> 299.16499
B18: B | D18: F | F18: J | I18: J-1 | L18: (JTJ)-1 | O18: ANOVA
A19: a | B19: =EXP('Exp Reg'!H19) -> 14.051352 | D19: =SUMPRODUCT(SUMPRODUCT($B$4:$B$14-B19*EXP(B20*$A$4:$A$14),EXP(B20*$A$4:$A$14))) -> 31.466771 | F19: =-SUMPRODUCT(EXP(2*B20*$A$4:$A$14)) -> -98.920438 | G19: =SUMPRODUCT(SUMPRODUCT($B$4:$B$14-2*B19*EXP(B20*$A$4:$A$14),EXP(B20*$A$4:$A$14),$A$4:$A$14)) -> -109434.31 | I19: {=MINVERSE(F19:G20)} -> -0.089057745 | J19: 7.1363648e-05 | L19: {=MINVERSE(MMULT(TRANSPOSE(F19:G20),F19:G20))} -> 0.007931287 | M19: -6.3554901e-06 | P19: df | Q19: SS | R19: MS | S19: F | T19: Significance F
A20: b | B20: ='Exp Reg'!H20 -> 0.016090979 | D20: =B19*SUMPRODUCT(SUMPRODUCT($B$4:$B$14-B19*EXP(B20*$A$4:$A$14),EXP(B20*$A$4:$A$14),$A$4:$A$14)) -> 45710.044 | F20: =G19 -> -109434.31 | G20: =B19*SUMPRODUCT(SUMPRODUCT($B$4:$B$14-2*B19*EXP(B20*$A$4:$A$14),EXP(B20*$A$4:$A$14),$A$4:$A$14^2)) -> -1.3656775e+08 | I20: 7.1363648e-05 | J20: -6.4507408e-08 | L20: -6.3554901e-06 | M20: 5.0927744e-09 | O20: Regression | P20: 1 | Q20: =DEVSQ(K4:K14) -> 4333.0059 | R20: =Q20/P20 -> 4333.0059 | S20: =R20/R21 -> 130.353 | T20: =FDIST(S20,P20,P21) -> 1.1753122e-06
O21: Residual | P21: 9 | Q21: =SUMPRODUCT((B4:B14-B31*EXP(B32*A4:A14))^2) -> 299.16499 | R21: =Q21/P21 -> 33.240554
A22: a | B22: {=B19:B20-MMULT(I19:J20,D19:D20)} -> 13.591676 | D22: =SUMPRODUCT(SUMPRODUCT($B$4:$B$14-B22*EXP(B23*$A$4:$A$14),EXP(B23*$A$4:$A$14))) -> -2.2474664 | F22: =-SUMPRODUCT(EXP(2*B23*$A$4:$A$14)) -> -110.93721 | G22: =SUMPRODUCT(SUMPRODUCT($B$4:$B$14-2*B22*EXP(B23*$A$4:$A$14),EXP(B23*$A$4:$A$14),$A$4:$A$14)) -> -123761.05 | I22: {=MINVERSE(F22:G23)} -> -0.10659293 | J22: 8.7467926e-05 | L22: {=MINVERSE(MMULT(TRANSPOSE(F22:G23),F22:G23))} -> 0.01136206 | M22: -9.3234691e-06 | O22: Total | P22: =COUNT(A4:A14)-1 -> 10 | Q22: =DEVSQ(B4:B14) -> 4542.5455
A23: b | B23: 0.016794032 | D23: =B22*SUMPRODUCT(SUMPRODUCT($B$4:$B$14-B22*EXP(B23*$A$4:$A$14),EXP(B23*$A$4:$A$14),$A$4:$A$14)) -> -1730.7024 | F23: =G22 -> -123761.05 | G23: =B22*SUMPRODUCT(SUMPRODUCT($B$4:$B$14-2*B22*EXP(B23*$A$4:$A$14),EXP(B23*$A$4:$A$14),$A$4:$A$14^2)) -> -1.5082161e+08 | I23: 8.7467926e-05 | J23: -7.8404698e-08 | L23: -9.3234691e-06 | M23: 7.650644e-09
P24: Coefficients | Q24: Standard Error | R24: t Stat | S24: P-value | T24: Lower 95% | U24: Upper 95%
A25: a | B25: {=B22:B23-MMULT(I22:J23,D22:D23)} -> 13.503493 | D25: =SUMPRODUCT(SUMPRODUCT($B$4:$B$14-B25*EXP(B26*$A$4:$A$14),EXP(B26*$A$4:$A$14))) -> 0.036187446 | F25: =-SUMPRODUCT(EXP(2*B26*$A$4:$A$14)) -> -112.05097 | G25: =SUMPRODUCT(SUMPRODUCT($B$4:$B$14-2*B25*EXP(B26*$A$4:$A$14),EXP(B26*$A$4:$A$14),$A$4:$A$14)) -> -124181.15 | I25: {=MINVERSE(F25:G26)} -> -0.10456456 | J25: 8.6297807e-05 | L25: {=MINVERSE(MMULT(TRANSPOSE(F25:G26),F25:G26))} -> 0.010933756 | M25: -9.0236995e-06 | O25: Intercept | P25: =B31 -> 13.504749 | Q25: =SQRT(L31*R21) -> 0.60304238 | R25: =P25/Q25 -> 22.394361 | S25: =TDIST(ABS(R25),P21,2) -> 3.3420876e-09 | T25: =P25-Q25*TINV(0.05,P21) -> 12.140572 | U25: =P25+Q25*TINV(0.05,P21) -> 14.868925
A26: b | B26: 0.016854918 | D26: =B25*SUMPRODUCT(SUMPRODUCT($B$4:$B$14-B25*EXP(B26*$A$4:$A$14),EXP(B26*$A$4:$A$14),$A$4:$A$14)) -> 29.29688 | F26: =G25 -> -124181.15 | G26: =B25*SUMPRODUCT(SUMPRODUCT($B$4:$B$14-2*B25*EXP(B26*$A$4:$A$14),EXP(B26*$A$4:$A$14),$A$4:$A$14^2)) -> -1.5046671e+08 | I26: 8.6297807e-05 | J26: -7.7868124e-08 | L26: -9.0236995e-06 | M26: 7.4473178e-09 | O26: x | P26: =B32 -> 0.016854076 | Q26: =SQRT(M32*R21) -> 0.00049765376 | R26: =P26/Q26 -> 33.867073 | S26: =TDIST(ABS(R26),P21,2) -> 8.4136531e-11 | T26: =P26-Q26*TINV(0.05,P21) -> 0.015728305 | U26: =P26+Q26*TINV(0.05,P21) -> 0.017979847
A28: a | B28: {=B25:B26-MMULT(I25:J26,D25:D26)} -> 13.504748 | D28: =SUMPRODUCT(SUMPRODUCT($B$4:$B$14-B28*EXP(B29*$A$4:$A$14),EXP(B29*$A$4:$A$14))) -> 7.582459e-06 | F28: =-SUMPRODUCT(EXP(2*B29*$A$4:$A$14)) -> -112.03549 | G28: =SUMPRODUCT(SUMPRODUCT($B$4:$B$14-2*B28*EXP(B29*$A$4:$A$14),EXP(B29*$A$4:$A$14),$A$4:$A$14)) -> -124176.07 | I28: {=MINVERSE(F28:G29)} -> -0.10459563 | J28: 8.631633e-05 | L28: {=MINVERSE(MMULT(TRANSPOSE(F28:G29),F28:G29))} -> 0.010940253 | M28: -9.0283175e-06
A29: b | B29: 0.016854076 | D29: =B28*SUMPRODUCT(SUMPRODUCT($B$4:$B$14-B28*EXP(B29*$A$4:$A$14),EXP(B29*$A$4:$A$14),$A$4:$A$14)) -> 0.0058190187 | F29: =G28 -> -124176.07 | G29: =B28*SUMPRODUCT(SUMPRODUCT($B$4:$B$14-2*B28*EXP(B29*$A$4:$A$14),EXP(B29*$A$4:$A$14),$A$4:$A$14^2)) -> -1.5047297e+08 | I29: 8.631633e-05 | J29: -7.7877262e-08 | L29: -9.0283175e-06 | M29: 7.4505148e-09
A31: a | B31: {=B28:B29-MMULT(I28:J29,D28:D29)} -> 13.504749 | D31: =SUMPRODUCT(SUMPRODUCT($B$4:$B$14-B31*EXP(B32*$A$4:$A$14),EXP(B32*$A$4:$A$14))) -> 2.8288483e-13 | F31: =-SUMPRODUCT(EXP(2*B32*$A$4:$A$14)) -> -112.03549 | G31: =SUMPRODUCT(SUMPRODUCT($B$4:$B$14-2*B31*EXP(B32*$A$4:$A$14),EXP(B32*$A$4:$A$14),$A$4:$A$14)) -> -124176.07 | I31: {=MINVERSE(F31:G32)} -> -0.10459564 | J31: 8.6316334e-05 | L31: {=MINVERSE(MMULT(TRANSPOSE(F31:G32),F31:G32))} -> 0.010940254 | M31: -9.0283184e-06
A32: b | B32: 0.016854076 | D32: =B31*SUMPRODUCT(SUMPRODUCT($B$4:$B$14-B31*EXP(B32*$A$4:$A$14),EXP(B32*$A$4:$A$14),$A$4:$A$14)) -> 1.4969294e-10 | F32: =G31 -> -124176.07 | G32: =B31*SUMPRODUCT(SUMPRODUCT($B$4:$B$14-2*B31*EXP(B32*$A$4:$A$14),EXP(B32*$A$4:$A$14),$A$4:$A$14^2)) -> -1.5047297e+08 | I32: 8.6316334e-05 | J32: -7.7877263e-08 | L32: -9.0283184e-06 | M32: 7.4505154e-09

Sheet Exp Reg4
A1: Exponential Regression
A3: x | B3: y | C3: pred y | D3: residual | E3: resid-sq | H3: ANOVA
A4: 45 | B4: 33 | C4: {=ExpPred(A4:A14,A4:A14,B4:B14)} -> #NAME? | D4: =B4-C4 -> #NAME? | E4: =D4^2 -> #NAME? | I4: df | J4: SS | K4: MS | L4: F | M4: Sig F
A5: 99 | B5: 72 | C5: #NAME? | D5: =B5-C5 -> #NAME? | E5: =D5^2 -> #NAME? | H5: Regression | I5: 1 | J5: =DEVSQ(C4:C14) -> #NAME? | K5: =J5/I5 -> #NAME? | L5: =K5/K6 -> #NAME? | M5: =FDIST(L5,I5,I6) -> #NAME?
A6: 31 | B6: 19 | C6: #NAME? | D6: =B6-C6 -> #NAME? | E6: =D6^2 -> #NAME? | H6: Residual | I6: 9 | J6: =E15 -> #NAME? | K6: =J6/I6 -> #NAME?
A7: 57 | B7: 27 | C7: #NAME? | D7: =B7-C7 -> #NAME? | E7: =D7^2 -> #NAME? | H7: Total | I7: =COUNT(A4:A14)-1 -> 10 | J7: =DEVSQ(B4:B14) -> 4542.5455
A8: 37 | B8: 23 | C8: #NAME? | D8: =B8-C8 -> #NAME? | E8: =D8^2 -> #NAME?
A9: 85 | B9: 62 | C9: #NAME? | D9: =B9-C9 -> #NAME? | E9: =D9^2 -> #NAME? | I9: Coeff | J9: Std Error | K9: t Stat | L9: P-value | M9: Lower 95% | N9: Upper 95%
A10: 21 | B10: 24 | C10: #NAME? | D10: =B10-C10 -> #NAME? | E10: =D10^2 -> #NAME? | H10: Intercept | I10: {=ExpCoeff(A4:A14,B4:B14)} -> #NAME? | J10: #NAME? | K10: =I10/J10 -> #NAME? | L10: =TDIST(ABS(K10),I6,2) -> #NAME? | M10: =I10-J10*TINV(0.05,I6) -> #NAME? | N10: =I10+J10*TINV(0.05,I6) -> #NAME?
A11: 64 | B11: 32 | C11: #NAME? | D11: =B11-C11 -> #NAME? | E11: =D11^2 -> #NAME? | H11: x | I11: #NAME? | J11: #NAME? | K11: =I11/J11 -> #NAME? | L11: =TDIST(ABS(K11),I6,2) -> #NAME? | M11: =I11-J11*TINV(0.05,I6) -> #NAME? | N11: =I11+J11*TINV(0.05,I6) -> #NAME?
A12: 17 | B12: 18 | C12: #NAME? | D12: =B12-C12 -> #NAME? | E12: =D12^2 -> #NAME?
A13: 41 | B13: 36 | C13: #NAME? | D13: =B13-C13 -> #NAME? | E13: =D13^2 -> #NAME?
A14: 103 | B14: 76 | C14: #NAME? | D14: =B14-C14 -> #NAME? | E14: =D14^2 -> #NAME? | I14: {=ExpCoeff(A4:A14,B4:B14,,TRUE)} -> #NAME? | J14: #NAME? | K14: #NAME? | L14: #NAME? | N14: x | O14: pred y | P14: x | Q14: pred y
E15: =SUM(E4:E14) -> #NAME? | H15: alpha | I15: #NAME? | J15: #NAME? | K15: #NAME? | L15: #NAME? | N15: 45 | O15: {=ExpPred(N15:N16,A4:A14,B4:B14)} -> #NAME? | P15: 45 | Q15: {=ExpPredC(P15:P16,B16,B17)} -> #NAME?
A16: α | B16: {=ExpCoeff(A4:A14,B4:B14)} -> #NAME? | H16: beta | I16: #NAME? | J16: #NAME? | K16: #NAME? | L16: #NAME? | N16: 50 | O16: #NAME? | P16: 50 | Q16: #NAME?
A17: β | B17: #NAME?

Sheet Exp Reg5
A1: Exponential Regression
A3: x | B3: y | D3: Exponential Regression Analysis
A4: 45 | B4: 33
A5: 99 | B5: 72 | D5: ANOVA | H5: Alpha | I5: 0.05
A6: 31 | B6: 19 | E6: df | F6: SS | G6: MS | H6: F | I6: p-value | J6: sig
A7: 57 | B7: 27 | D7: Regression | E7: 1 | F7: =DEVSQ(ExpPredC(A4:A14,E12,E13)) -> #NAME? | G7: =F7/E7 -> #NAME? | H7: =G7/G8 -> #NAME? | I7: =FDIST(H7,E7,E8) -> #NAME? | J7: =IF(I7<I5,"yes","no") -> #NAME?
A8: 37 | B8: 23 | D8: Residual | E8: =E9-E7 -> 9 | F8: {=SUMSQ(ExpPredC(A4:A14,E12,E13)-B4:B14)} -> #NAME? | G8: =F8/E8 -> #NAME?
A9: 85 | B9: 62 | D9: Total | E9: =COUNT(B4:B14)-1 -> 10 | F9: =DEVSQ(B4:B14) -> 4542.5455
A10: 21 | B10: 24
A11: 64 | B11: 32 | E11: coeff | F11: std err | G11: t stat | H11: p-value | I11: lower | J11: upper
A12: 17 | B12: 18 | D12: Intercept | E12: {=ExpCoeff(A4:A14,B4:B14)} -> #NAME? | F12: #NAME? | G12: =E12/F12 -> #NAME? | H12: =TDIST(ABS(G12),$E$8,2) -> #NAME? | I12: =E12-TINV(I$5,$E$8)*F12 -> #NAME? | J12: =E12+TINV(I$5,$E$8)*F12 -> #NAME?
A13: 41 | B13: 36 | D13: =A3 -> x | E13: #NAME? | F13: #NAME? | G13: =E13/F13 -> #NAME? | H13: =TDIST(ABS(G13),$E$8,2) -> #NAME? | I13: =E13-TINV(I$5,$E$8)*F13 -> #NAME? | J13: =E13+TINV(I$5,$E$8)*F13 -> #NAME?
A14: 103 | B14: 76

Sheet Pow Reg
A1: Power Regression
A3: Original Data | D3: Log Transformed Data | G3: SUMMARY OUTPUT | O3: Use of slope and intercept for prediction
A5: x | B5: y | D5: ln x | E5: ln y | G5: Regression Statistics | O5: x | P5: y
A6: 8.1 | B6: 33 | D6: =LN(A6) -> 2.0918641 | E6: =LN(B6) -> 3.4965076 | G6: Multiple R | H6: 0.75380689 | O6: 25 | P6: =$H$22*$H$23^LN(O6) -> 35.421098
A7: 69.9 | B7: 49 | D7: =LN(A7) -> 4.2470656 | E7: =LN(B7) -> 3.8918203 | G7: R Square | H7: 0.56822483 | O7: 35 | P7: =$H$22*$H$23^LN(O7) -> 38.327608
A8: 4.2 | B8: 19 | D8: =LN(A8) -> 1.4350845 | E8: =LN(B8) -> 2.944439 | G8: Adjusted R Square | H8: 0.52024982
A9: 14.1 | B9: 27 | D9: =LN(A9) -> 2.6461748 | E9: =LN(B9) -> 3.2958369 | G9: Standard Error | H9: 0.21085977 | O9: Use of TREND
A10: 5.6 | B10: 23 | D10: =LN(A10) -> 1.7227666 | E10: =LN(B10) -> 3.1354942 | G10: Observations | H10: 11
A11: 52.1 | B11: 51 | D11: =LN(A11) -> 3.9531649 | E11: =LN(B11) -> 3.9318256 | O11: x | P11: y
A12: 44.6 | B12: 34 | D12: =LN(A12) -> 3.7977339 | E12: =LN(B12) -> 3.5263605 | G12: ANOVA | O12: 25 | P12: {=EXP(TREND(LN(B6:B16),LN(A6:A16),LN(O12:O13)))} -> 35.421098
A13: 19.6 | B13: 32 | D13: =LN(A13) -> 2.9755296 | E13: =LN(B13) -> 3.4657359 | H13: df | I13: SS | J13: MS | K13: F | L13: Significance F | O13: 35 | P13: 38.327608
A14: 33 | B14: 28 | D14: =LN(A14) -> 3.4965076 | E14: =LN(B14) -> 3.3322045 | G14: Regression | H14: 1 | I14: 0.52661416 | J14: 0.52661416 | K14: 11.844182 | L14: 0.0073725828
A15: 6.7 | B15: 36 | D15: =LN(A15) -> 1.9021075 | E15: =LN(B15) -> 3.5835189 | G15: Residual | H15: 9 | I15: 0.4001566 | J15: 0.044461844 | O15: 26 | P15: =EXP(TREND(LN(B6:B16),LN(A6:A16),LN(O15))) -> 35.748211
A16: 30.1 | B16: 43 | D16: =LN(A16) -> 3.4045252 | E16: =LN(B16) -> 3.7612001 | G16: Total | H16: 10 | I16: 0.92677076
H18: Coefficients | I18: Standard Error | J18: t Stat | K18: P-value | L18: Lower 95% | M18: Upper 95%
A19: r | B19: =CORREL(E6:E16,D6:D16) -> 0.75380689 | G19: Intercept | H19: 2.8128629 | I19: 0.20614121 | J19: 13.645321 | K19: 2.5593094e-07 | L19: 2.3465391 | M19: 3.2791867
G20: ln x | H20: 0.23438143 | I20: 0.068103695 | J20: 3.4415377 | K20: 0.0073725828 | L20: 0.080320171 | M20: 0.38844269
G22: ea | H22: =EXP(H19) -> 16.657539 | J22: x | K22: 26
G23: eb | H23: =EXP(H20) -> 1.2641266 | J23: y | K23: =H22*H23^LN(K22) -> 35.748211

Sheet Reg T 1
A1: Two Sample t-Test by Regression
A3: New | B3: Old | D3: x | E3: y | G3: SUMMARY OUTPUT | O3: t-Test: Two-Sample Assuming Equal Variances | S3: Comparison
A4: 13 | B4: 12 | D4: 0 | E4: 13
A5: 17 | B5: 8 | D5: 0 | E5: 17 | G5: Regression Statistics | P5: New | Q5: Old | S5: F | T5: =K14 -> 4.7383178
A6: 19 | B6: 6 | D6: 0 | E6: 19 | G6: Multiple R | H6: 0.45649174 | O6: Mean | P6: 15 | Q6: 11.1 | S6: t2 | T6: =P12^2 -> 4.7383178
A7: 11 | B7: 16 | D7: 0 | E7: 11 | G7: R Square | H7: 0.20838471 | O7: Variance | P7: 13.333333 | Q7: 18.766667
A8: 20 | B8: 12 | D8: 0 | E8: 20 | G8: Adjusted R Square | H8: 0.16440608 | O8: Observations | P8: 10 | Q8: 10 | S8: Sig F | T8: =L14 -> 0.043052717
A9: 15 | B9: 14 | D9: 0 | E9: 15 | G9: Standard Error | H9: 4.0062451 | O9: Pooled Variance | P9: 16.05 | S9: P(T<t) two-tail | T9: =P15 -> 0.043052715
A10: 18 | B10: 10 | D10: 0 | E10: 18 | G10: Observations | H10: 20 | O10: Hypothesized Mean Difference | P10: 0
A11: 9 | B11: 18 | D11: 0 | E11: 9 | O11: df | P11: 18 | S11: Multiple R | T11: =H6 -> 0.45649174
A12: 12 | B12: 4 | D12: 0 | E12: 12 | G12: ANOVA | O12: t Stat | P12: 2.1767677 | S12: df | T12: =18 -> 18
A13: 16 | B13: 11 | D13: 0 | E13: 16 | H13: df | I13: SS | J13: MS | K13: F | L13: Significance F | O13: P(T<=t) one-tail | P13: 0.021526358 | S13: √(F/(F+df)) | T13: =SQRT(T5/(T5+T12)) -> 0.45649174
D14: 1 | E14: 12 | G14: Regression | H14: 1 | I14: 76.05 | J14: 76.05 | K14: 4.7383178 | L14: 0.043052717 | O14: t Critical one-tail | P14: 1.7340636
D15: 1 | E15: 8 | G15: Residual | H15: 18 | I15: 288.9 | J15: 16.05 | O15: P(T<=t) two-tail | P15: 0.043052715
D16: 1 | E16: 6 | G16: Total | H16: 19 | I16: 364.95 | O16: t Critical two-tail | P16: 2.100922
D17: 1 | E17: 16
D18: 1 | E18: 12 | H18: Coefficients | I18: Standard Error | J18: t Stat | K18: P-value | L18: Lower 95% | M18: Upper 95%
D19: 1 | E19: 14 | G19: Intercept | H19: 15 | I19: 1.2668859 | J19: 11.840056 | K19: 6.2614482e-10 | L19: 12.338371 | M19: 17.661629
D20: 1 | E20: 10 | G20: x | H20: -3.9 | I20: 1.7916473 | J20: -2.1767677 | K20: 0.043052717 | L20: -7.6641113 | M20: -0.13588873
D21: 1 | E21: 18
D22: 1 | E22: 4
D23: 1 | E23: 11

Sheet Reg T 1A
A1: SUMMARY OUTPUT
A3: Regression Statistics
A4: Multiple R | B4: 0.45649174
A5: R Square | B5: 0.20838471
A6: Adjusted R Square | B6: 0.16440608
A7: Standard Error | B7: 4.0062451
A8: Observations | B8: 20
A10: ANOVA
B11: df | C11: SS | D11: MS | E11: F | F11: Significance F
A12: Regression | B12: 1 | C12: 76.05 | D12: 76.05 | E12: 4.7383178 | F12: 0.043052717
A13: Residual | B13: 18 | C13: 288.9 | D13: 16.05
A14: Total | B14: 19 | C14: 364.95
B16: Coefficients | C16: Standard Error | D16: t Stat | E16: P-value | F16: Lower 95% | G16: Upper 95%
A17: Intercept | B17: 15 | C17: 1.2668859 | D17: 11.840056 | E17: 6.2614482e-10 | F17: 12.338371 | G17: 17.661629
A18: x | B18: -3.9 | C18: 1.7916473 | D18: -2.1767677 | E18: 0.043052717 | F18: -7.6641113 | G18: -0.13588873
A22: RESIDUAL OUTPUT | F22: PROBABILITY OUTPUT
A24: Observation | B24: Predicted y | C24: Residuals | D24: Standard Residuals | F24: Percentile | G24: y
A25: 1 | B25: 15 | C25: -2 | D25: -0.51290039 | F25: 2.5 | G25: 4
A26: 2 | B26: 15 | C26: 2 | D26: 0.51290039 | F26: 7.5 | G26: 6
A27: 3 | B27: 15 | C27: 4 | D27: 1.0258008 | F27: 12.5 | G27: 8
A28: 4 | B28: 15 | C28: -4 | D28: -1.0258008 | F28: 17.5 | G28: 9
A29: 5 | B29: 15 | C29: 5 | D29: 1.282251 | F29: 22.5 | G29: 10
A30: 6 | B30: 15 | C30: 0 | D30: 0 | F30: 27.5 | G30: 11
A31: 7 | B31: 15 | C31: 3 | D31: 0.76935058 | F31: 32.5 | G31: 11
A32: 8 | B32: 15 | C32: -6 | D32: -1.5387012 | F32: 37.5 | G32: 12
A33: 9 | B33: 15 | C33: -3 | D33: -0.76935058 | F33: 42.5 | G33: 12
A34: 10 | B34: 15 | C34: 1 | D34: 0.25645019 | F34: 47.5 | G34: 12
A35: 11 | B35: 11.1 | C35: 0.9 | D35: 0.23080517 | F35: 52.5 | G35: 13
A36: 12 | B36: 11.1 | C36: -3.1 | D36: -0.7949956 | F36: 57.5 | G36: 14
... A44: 20 | B44: 11.1 | C44: -0.1 | D44: -0.025645019 | F44: 97.5 | G44: 20

Sheet Reg T 2
A1: Two Sample t-Test by Regression
A3: New | B3: Old | D3: x | E3: y | G3: SUMMARY OUTPUT | O3: t-Test: Two-Sample Assuming Equal Variances | S3: t-Test: Two-Sample Assuming Unequal Variances
A4: 34 | B4: 12 | D4: 0 | E4: 34
A5: 52 | B5: 8 | D5: 0 | E5: 52 | G5: Regression Statistics | P5: New | Q5: Old | T5: New | U5: Old
A6: 17 | B6: 6 | D6: 0 | E6: 17 | G6: Multiple R | H6: 0.63143952 | O6: Mean | P6: 33.5 | Q6: 11.1 | S6: Mean | T6: 33.5 | U6: 11.1
A7: 45 | B7: 16 | D7: 0 | E7: 45 | G7: R Square | H7: 0.39871587 | O7: Variance | P7: 401.61111 | Q7: 18.766667 | S7: Variance | T7: 401.61111 | U7: 18.766667
A8: 5 | B8: 12 | D8: 0 | E8: 5 | G8: Adjusted R Square | H8: 0.3653112 | O8: Observations | P8: 10 | Q8: 10 | S8: Observations | T8: 10 | U8: 10
A9: 29 | B9: 14 | D9: 0 | E9: 29 | G9: Standard Error | H9: 14.497893 | O9: Pooled Variance | P9: 210.18889 | S9: Hypothesized Mean Difference | T9: 0
A10: 31 | B10: 10 | D10: 0 | E10: 31 | G10: Observations | H10: 20 | O10: Hypothesized Mean Difference | P10: 0 | S10: df | T10: 10
A11: 6 | B11: 18 | D11: 0 | E11: 6 | O11: df | P11: 18 | S11: t Stat | T11: 3.4548416
A12: 52 | B12: 4 | D12: 0 | E12: 52 | G12: ANOVA | O12: t Stat | P12: 3.4548416 | S12: P(T<=t) one-tail | T12: 0.0030879404
A13: 64 | B13: 11 | D13: 0 | E13: 64 | H13: df | I13: SS | J13: MS | K13: F | L13: Significance F | O13: P(T<=t) one-tail | P13: 0.0014131154 | S13: t Critical one-tail | T13: 1.8124611
D14: 1 | E14: 12 | G14: Regression | H14: 1 | I14: 2508.8 | J14: 2508.8 | K14: 11.935931 | L14: 0.0028262308 | O14: t Critical one-tail | P14: 1.7340636 | S14: P(T<=t) two-tail | T14: 0.0061758809
D15: 1 | E15: 8 | G15: Residual | H15: 18 | I15: 3783.4 | J15: 210.18889 | O15: P(T<=t) two-tail | P15: 0.0028262308 | S15: t Critical two-tail | T15: 2.2281388
D16: 1 | E16: 6 | G16: Total | H16: 19 | I16: 6292.2 | O16: t Critical two-tail | P16: 2.100922
D17: 1 | E17: 16
D18: 1 | E18: 12 | H18: Coefficients | I18: Standard Error | J18: t Stat | K18: P-value | L18: Lower 95% | M18: Upper 95%
D19: 1 | E19: 14 | G19: Intercept | H19: 33.5 | I19: 4.5846362 | J19: 7.3070138 | K19: 8.687209e-07 | L19: 23.868037 | M19: 43.131963
D20: 1 | E20: 10 | G20: x | H20: -22.4 | I20: 6.4836547 | J20: -3.4548416 | K20: 0.0028262308 | L20: -36.021653 | M20: -8.778347
D21: 1 | E21: 18
D22: 1 | E22: 4
D23: 1 | E23: 11

Sheet Reg T 2A
A1: SUMMARY OUTPUT
A3: Regression Statistics
A4: Multiple R | B4: 0.63143952
A5: R Square | B5: 0.39871587
A6: Adjusted R Square | B6: 0.3653112
A7: Standard Error | B7: 14.497893
A8: Observations | B8: 20
A10: ANOVA
B11: df | C11: SS | D11: MS | E11: F | F11: Significance F
A12: Regression | B12: 1 | C12: 2508.8 | D12: 2508.8 | E12: 11.935931 | F12: 0.0028262308
A13: Residual | B13: 18 | C13: 3783.4 | D13: 210.18889
A14: Total | B14: 19 | C14: 6292.2
B16: Coefficients | C16: Standard Error | D16: t Stat | E16: P-value | F16: Lower 95% | G16: Upper 95%
A17: Intercept | B17: 33.5 | C17: 4.5846362 | D17: 7.3070138 | E17: 8.687209e-07 | F17: 23.868037 | G17: 43.131963
A18: x | B18: -22.4 | C18: 6.4836547 | D18: -3.4548416 | E18: 0.0028262308 | F18: -36.021653 | G18: -8.778347
A22: RESIDUAL OUTPUT | F22: PROBABILITY OUTPUT
A24: Observation | B24: Predicted y | C24: Residuals | D24: Standard Residuals | F24: Percentile | G24: y
A25: 1 | B25: 33.5 | C25: 0.5 | D25: 0.035432816 | F25: 2.5 | G25: 4
A26: 2 | B26: 33.5 | C26: 18.5 | D26: 1.3110142 | F26: 7.5 | G26: 5
A27: 3 | B27: 33.5 | C27: -16.5 | D27: -1.1692829 | F27: 12.5 | G27: 6
A28: 4 | B28: 33.5 | C28: 11.5 | D28: 0.81495478 | F28: 17.5 | G28: 6
A29: 5 | B29: 33.5 | C29: -28.5 | D29: -2.0196705 | F29: 22.5 | G29: 8
A30: 6 | B30: 33.5 | C30: -4.5 | D30: -0.31889535 | F30: 27.5 | G30: 10
A31: 7 | B31: 33.5 | C31: -2.5 | D31: -0.17716408 | F31: 32.5 | G31: 11
A32: 8 | B32: 33.5 | C32: -27.5 | D32: -1.9488049 | F32: 37.5 | G32: 12
A33: 9 | B33: 33.5 | C33: 18.5 | D33: 1.3110142 | F33: 42.5 | G33: 12
A34: 10 | B34: 33.5 | C34: 30.5 | D34: 2.1614018 | F34: 47.5 | G34: 14
A35: 11 | B35: 11.1 | C35: 0.9 | D35: 0.06377907 | F35: 52.5 | G35: 16
A36: 12 | B36: 11.1 | C36: -3.1 | D36: -0.21968346 | F36: 57.5 | G36: 17
... A44: 20 | B44: 11.1 | C44: -0.1 | D44: -0.0070865633 | F44: 97.5 | G44: 64

Sheet TReg
A1: Total Least Squares Regression
A3: Cig | B3: Life Exp | I3: Regression Analysis | Q3: TLS
A4: 5 | B4: 80 | D4: x̅ | E4: =AVERAGE(A4:A18) -> 19.4 | G4: =FTEXT(E4) -> #NAME?
A5: 23 | B5: 78 | D5: y̅ | E5: =AVERAGE(B4:B18) -> 73.533333 | G5: =FTEXT(E5) -> #NAME? | I5: OVERALL FIT | Q5: Cig | R5: Life Exp
A6: 25 | B6: 60 | D6: n | E6: =COUNT(A4:A18) -> 15 | G6: =FTEXT(E6) -> #NAME? | I6: Multiple R | J6: =SQRT(J7) -> #NAME? | L6: AIC | M6: =J10*LN(K15/J10)+2*(J14+1) -> #NAME? | Q6: 5 | R6: =Q6*$E$11+$E$10 -> 85.586857
A7: 48 | B7: 53 | D7: w | E7: =DEVSQ(B4:B18)-DEVSQ(A4:A18) -> -487.86667 | G7: =FTEXT(E7) -> #NAME? | I7: R Square | J7: =K14/K16 -> #NAME? | L7: AICc | M7: =M6+2*(J14+2)*(J14+3)/(J10-J14-3) -> #NAME? | Q7: 23 | R7: =Q7*$E$11+$E$10 -> 70.519952
A8: 17 | B8: 85 | D8: r | E8: =2*COVAR(A4:A18,B4:B18)*E6 -> -2728.4 | G8: =FTEXT(E8) -> #NAME? | I8: Adjusted R Square | J8: =1-(1-J7)*(J10-1)/(J10-J14-1) -> #NAME? | L8: SBC | M8: =J10*LN(K15/J10)+(J14+1)*LN(J10) -> #NAME? | Q8: 25 | R8: =Q8*$E$11+$E$10 -> 68.845852
A9: 8 | B9: 84 | I9: Standard Error | J9: =SQRT(L15) -> #NAME? | Q9: 48 | R9: =Q9*$E$11+$E$10 -> 49.593695
A10: 4 | B10: 73 | D10: a | E10: =E5-E4*E11 -> 89.772109 | G10: =FTEXT(E10) -> #NAME? | I10: Observations | J10: =COUNT(B4:B18) -> 15 | Q10: 17 | R10: =Q10*$E$11+$E$10 -> 75.542254
A11: 26 | B11: 79 | D11: b | E11: =(E7+SQRT(E7^2+E8^2))/E8 -> -0.83705028 | G11: =FTEXT(E11) -> #NAME? | Q11: 8 | R11: =Q11*$E$11+$E$10 -> 83.075707
A12: 11 | B12: 81 | I12: ANOVA | M12: Alpha | N12: 0.05 | Q12: 4 | R12: =Q12*$E$11+$E$10 -> 86.423908
A13: 19 | B13: 75 | D13: a | E13: {=TRegCoeff0(A4:A18,B4:B18)} -> #NAME? | G13: =FTEXT(E13) -> #NAME? | J13: df | K13: SS | L13: MS | M13: F | N13: p-value | O13: sig | Q13: 26 | R13: =Q13*$E$11+$E$10 -> 68.008801
A14: 14 | B14: 68 | D14: b | E14: #NAME? | I14: Regression | J14: =COUNT(A4) -> 1 | K14: =DEVSQ(MMULT(DESIGN(A4:A18),J19:J20)) -> #NAME? | L14: =K14/J14 -> #NAME? | M14: =L14/L15 -> #NAME? | N14: =FDIST(M14,J14,J15) -> #NAME? | O14: =IF(N14<N12,"yes","no") -> #NAME? | Q14: 11 | R14: =Q14*$E$11+$E$10 -> 80.564556
A15: 35 | B15: 72 | I15: Residual | J15: =J16-J14 -> 13 | K15: =K16-K14 -> #NAME? | L15: =K15/J15 -> #NAME? | Q15: 19 | R15: =Q15*$E$11+$E$10 -> 73.868153
A16: 29 | B16: 58 | D16: a | E16: {=TRegCoeff(A4:A18,B4:B18)} -> #NAME? | G16: =FTEXT(E16) -> #NAME? | I16: Total | J16: =J10-1 -> 14 | K16: =DEVSQ(B4:B18) -> 1683.7333 | Q16: 14 | R16: =Q16*$E$11+$E$10 -> 78.053405
A17: 4 | B17: 92 | D17: b | E17: #NAME? | Q17: 35 | R17: =Q17*$E$11+$E$10 -> 60.475349
A18: 23 | B18: 65 | J18: coeff | K18: std err | L18: t stat | M18: p-value | N18: lower | O18: upper | Q18: 29 | R18: =Q18*$E$11+$E$10 -> 65.497651
I19: Intercept | J19: {=RegCoeff(A4:A18,B4:B18)} -> #NAME? | K19: #NAME? | L19: =J19/K19 -> #NAME? | M19: =TDIST(ABS(L19),$J$15,2) -> #NAME? | N19: =J19-TINV(N$12,$J$15)*K19 -> #NAME? | O19: =J19+TINV(N$12,$J$15)*K19 -> #NAME? | Q19: 4 | R19: =Q19*$E$11+$E$10 -> 86.423908
I20: {=TRANSPOSE(A3)} -> Cig | J20: #NAME? | K20: #NAME? | L20: =J20/K20 -> #NAME? | M20: =TDIST(ABS(L20),$J$15,2) -> #NAME? | N20: =J20-TINV(N$12,$J$15)*K20 -> #NAME? | O20: =J20+TINV(N$12,$J$15)*K20 -> #NAME? | Q20: 23 | R20: =Q20*$E$11+$E$10 -> 70.519952

Sheet Dem 1
A1: Deming Regression - Known Variances
A3: Subject | B3: x | C3: y | E3: Regression coefficients | J3: Residuals Report | U3: Shapiro-Wilk Test | AE3: QQ Plot - opt res
A4: 1 | B4: 5.1 | C4: 5.4
A5: 2 | B5: 5.6 | C5: 5.6 | E5: x̅ | F5: =AVERAGE(B4:B13) -> 5.6 | H5: =FTEXT(F5) -> #NAME? | J5: Subject | K5: x | L5: y | M5: pred y | N5: x-hat | O5: y-hat | P5: raw res | Q5: x-res | R5: y-res | S5: opt res | V5: =S5 -> opt res | AE5: Count | AF5: =COUNT(S6:S15) -> 10 | AG5: =2*AF5 -> 20
A6: 3 | B6: 6.8 | C6: 6.3 | E6: y̅ | F6: =AVERAGE(C4:C13) -> 5.53 | H6: =FTEXT(F6) -> #NAME? | J6: 1 | K6: =B4 -> 5.1 | L6: =C4 -> 5.4 | M6: =F$12+K6*F$13 -> 5.0210001 | N6: =K6+$F$11*$F$13*P6/($F$11*$F$13^2+1) -> 5.3686176 | O6: =L6-P6/($F$11*$F$13^2+1) -> 5.2944528 | P6: =L6-M6 -> 0.37899992 | Q6: =K6-N6 -> -0.26861763 | R6: =L6-O6 -> 0.10554722 | S6: =SIGN(P6)*SQRT(Q6^2+$F$11*R6^2) -> 0.3162372 | U6: W | V6: =SHAPIRO(S6:S15) -> #NAME? | AE6: Mean | AF6: =AVERAGE(S6:S15) -> 1.2878587e-15
A7: 4 | B7: 5.9 | C7: 6.1 | E7: u | F7: =DEVSQ(B4:B13) -> 7.92 | H7: =FTEXT(F7) -> #NAME? | J7: 2 | K7: =B5 -> 5.6 | L7: =C5 -> 5.6 | M7: =F$12+K7*F$13 -> 5.53 | N7: =K7+$F$11*$F$13*P7/($F$11*$F$13^2+1) -> 5.6496128 | O7: =L7-P7/($F$11*$F$13^2+1) -> 5.5805058 | P7: =L7-M7 -> 0.07 | Q7: =K7-N7 -> -0.049612765 | R7: =L7-O7 -> 0.019494213 | S7: =SIGN(P7)*SQRT(Q7^2+$F$11*R7^2) -> 0.058407939 | U7: p-value | V7: =SWTEST(S6:S15) -> #NAME? | AE7: Std Dev | AF7: =STDEV(S6:S15) -> 0.35621511
A8: 5 | B8: 4 | C8: 4.7 | E8: v | F8: =DEVSQ(C4:C13) -> 7.481 | H8: =FTEXT(F8) -> #NAME? | J8: 3 | K8: =B6 -> 6.8 | L8: =C6 -> 6.3 | M8: =F$12+K8*F$13 -> 6.7515998 | N8: =K8+$F$11*$F$13*P8/($F$11*$F$13^2+1) -> 6.4799269 | O8: =L8-P8/($F$11*$F$13^2+1) -> 6.4257655 | P8: =L8-M8 -> -0.4515998 | Q8: =K8-N8 -> 0.32007307 | R8: =L8-O8 -> -0.12576547 | S8: =SIGN(P8)*SQRT(Q8^2+$F$11*R8^2) -> -0.37681448 | U8: alpha | V8: 0.05
A9: 6 | B9: 5.6 | C9: 5.1 | E9: r | F9: =SUMPRODUCT(B4:B13-F5,C4:C13-F6) -> 6.9 | H9: =FTEXT(F9) -> #NAME? | J9: 4 | K9: =B7 -> 5.9 | L9: =C7 -> 6.1 | M9: =F$12+K9*F$13 -> 5.8354 | N9: =K9+$F$11*$F$13*P9/($F$11*$F$13^2+1) -> 6.0875363 | O9: =L9-P9/($F$11*$F$13^2+1) -> 6.0263119 | P9: =L9-M9 -> 0.26460005 | Q9: =K9-N9 -> -0.18753629 | R9: =L9-O9 -> 0.07368814 | S9: =SIGN(P9)*SQRT(Q9^2+$F$11*R9^2) -> 0.22078205 | U9: normal | V9: =IF(V7<V8,"no","yes") -> #NAME? | AE9: Interval | AF9: Data | AG9: Std Norm | AH9: Std Data
